<!--
=============================================================
PISTA 2 — PALLETS
=============================================================
Obstáculo: Pallets (tarimas) distribuidos en chicana.
El robot debe navegar sorteando los pallets sin quedar atrapado.

Elementos animados: NINGUNO (pista estática).
  La física es 100% sólidos rígidos.

Meshes requeridos en ./meshes/pallets/:
  base_link.stl  (estructura completa de pallets, sólo visual)
  [+ meshes del robot en ./meshes/]

Nota sobre la malla:
  El URDF reporta centroide del mesh en (-0.27, 3.49, 0.08) m.
  El body está posicionado para que el centroide quede en (2.73, 0, 0.08):
    body pos=(3, -3.49, 0), sin rotación.
  Si el resultado visual no coincide con los colisionadores,
  ajusta el pos o el euler del body "pallets_mesh_body".

Colisionadores box (no dependen del STL, siempre activos):
  3 filas de 2 pallets en chicana (6 pallets total):
    Fila A: x=2.5m, y=±0.7m  (obstrucción derecha e izquierda)
    Fila B: x=3.5m, y= 0.0m  (obstrucción central)
    Fila C: x=4.5m, y=±0.7m  (segunda chicana)
  Pallet: 1.20m × 0.80m × 0.15m, piso en z=0.

Layout qpos (nq = 29 robot, sin DOF extra de pista):
  [0:7]   base_freejoint   [7..12] flippers
  [13:19] arm              [19:21] fingers
  [21:27] drive wheels
=============================================================
-->
<mujoco model="aesir_pista_pallets">

  <compiler angle="radian" autolimits="true" meshdir="meshes"/>
  <option timestep="0.002" iterations="50" tolerance="1e-10"
          solver="Newton" integrator="implicitfast"
          cone="elliptic" impratio="10"/>
  <size njmax="1000" nconmax="500" nstack="2000000"/>

  <visual>
    <headlight diffuse="0.6 0.6 0.6" ambient="0.3 0.3 0.3" specular="0 0 0"/>
    <rgba haze="0.15 0.25 0.35 1"/>
    <global azimuth="120" elevation="-20"/>
    <map znear="0.01" zfar="50"/>
  </visual>

  <default>
    <default class="wheel">
      <geom type="cylinder" friction="1.5 0.01 0.001" condim="6" rgba="0.1 0.1 0.1 1"/>
    </default>
    <default class="track_wheel">
      <geom type="cylinder" friction="2.0 0.02 0.002" condim="6" rgba="0.05 0.05 0.05 1"/>
    </default>
    <default class="lidar_ray">
      <site type="sphere" size="0.003" rgba="1 0 0 0.4" group="3"/>
    </default>
    <!-- Pallets: madera, alta fricción -->
    <default class="pallet">
      <geom type="box" size="0.60 0.40 0.075"
            friction="0.8 0.01 0.001" condim="3"
            rgba="0.55 0.38 0.18 1"/>
    </default>
  </default>

  <asset>
    <mesh name="base_link"     file="base_link.stl"     scale="0.001 0.001 0.001"/>
    <mesh name="tracked_1"     file="tracked_1.stl"     scale="0.001 0.001 0.001"/>
    <mesh name="tracked_2"     file="tracked_2.stl"     scale="0.001 0.001 0.001"/>
    <mesh name="flipper_1_1"   file="flipper_1_1.stl"   scale="0.001 0.001 0.001"/>
    <mesh name="flipper_2_1"   file="flipper_2_1.stl"   scale="0.001 0.001 0.001"/>
    <mesh name="flipper_3_1"   file="flipper_3_1.stl"   scale="0.001 0.001 0.001"/>
    <mesh name="flipper_4_1"   file="flipper_4_1.stl"   scale="0.001 0.001 0.001"/>
    <mesh name="lidar"         file="lidar.stl"         scale="0.001 0.001 0.001"/>
    <mesh name="logitech_c920" file="logitech_c920.stl" scale="0.001 0.001 0.001"/>
    <!-- Mesh visual del conjunto de pallets (sólo visual) -->
    <mesh name="pallets_mesh"  file="pallets/base_link.stl" scale="0.001 0.001 0.001"/>

    <texture name="texplane" type="2d" builtin="checker"
             rgb1=".2 .3 .4" rgb2=".1 0.15 0.2" width="512" height="512"/>
    <material name="matplane"  reflectance="0.3" texture="texplane"
              texrepeat="4 4" texuniform="true"/>
    <material name="matpallet" rgba="0.55 0.38 0.18 1"/>
    <material name="matwall"   rgba="0.55 0.50 0.45 1"/>
  </asset>

  <worldbody>
    <light directional="true" diffuse=".8 .8 .8" specular=".2 .2 .2"
           pos="0 0 5" dir="0 0 -1"/>
    <light directional="false" pos="3.5 0 3" dir="-1 0 -1" diffuse="0.4 0.4 0.4"/>
    <geom name="floor" type="plane" size="12 12 0.1" pos="0 0 0" material="matplane"/>

    <!-- Cámaras -->
    <camera name="cam_overview" pos="3.5 0 7" euler="0 0 -1.5707" fovy="65" mode="fixed"/>
    <camera name="cam_door"     pos="6.5 0 1.5" euler="1.3 1.5707 0"
            fovy="55" mode="targetbody" target="footprint_link"/>

    <!-- ================== ROBOT AESIR ================== -->
    <body name="footprint_link" pos="0 0 0.20">
      <freejoint name="base_freejoint"/>
      <inertial pos="0 0 0.06" mass="25.0" diaginertia="1.2 1.6 2.7"/>
      <camera name="cam_chase" pos="-0.9 0 0.7" xyaxes="0 -1 0 0.5 0 1" fovy="65" mode="fixed"/>

      <geom name="chassis_col"    type="box" size="0.30 0.18 0.03"
            pos="0 0 0.12" rgba="0.30 0.32 0.36 0.1" friction="0.5 0.01 0.001"/>
      <geom name="chassis_visual" type="box" size="0.30 0.18 0.05"
            pos="0 0 0.10" rgba="0.30 0.32 0.36 1" contype="0" conaffinity="0"/>
      <geom pos="0 0.55 0" type="mesh" mesh="base_link"  rgba="0.75 0.75 0.75 1" contype="0" conaffinity="0"/>
      <geom pos="0 0.55 0" type="mesh" mesh="tracked_1"  rgba="0.75 0.75 0.75 1" contype="0" conaffinity="0"/>
      <geom pos="0 0.562 0" type="mesh" mesh="tracked_2" rgba="0.75 0.75 0.75 1" contype="0" conaffinity="0"/>
      <geom size="0.06 0.07915" pos="0.12 0 0.13915" type="cylinder" rgba="0.2 0.2 0.2 1"/>

      <body name="sensor_lidar" pos="0.32 0 0.105">
        <geom type="mesh" mesh="lidar" rgba="0.2 0.2 0.2 1" contype="0" conaffinity="0"/>
        <site name="lidar_origin"  pos="0 0 0.03" type="sphere" size="0.005" rgba="1 0 0 1"/>
        <site name="lidar_ray_00"  pos="0 0 0.03" class="lidar_ray" zaxis=" 1.00000  0.00000 0"/>
        <site name="lidar_ray_01"  pos="0 0 0.03" class="lidar_ray" zaxis=" 0.92388  0.38268 0"/>
        <site name="lidar_ray_02"  pos="0 0 0.03" class="lidar_ray" zaxis=" 0.70711  0.70711 0"/>
        <site name="lidar_ray_03"  pos="0 0 0.03" class="lidar_ray" zaxis=" 0.38268  0.92388 0"/>
        <site name="lidar_ray_04"  pos="0 0 0.03" class="lidar_ray" zaxis=" 0.00000  1.00000 0"/>
        <site name="lidar_ray_05"  pos="0 0 0.03" class="lidar_ray" zaxis="-0.38268  0.92388 0"/>
        <site name="lidar_ray_06"  pos="0 0 0.03" class="lidar_ray" zaxis="-0.70711  0.70711 0"/>
        <site name="lidar_ray_07"  pos="0 0 0.03" class="lidar_ray" zaxis="-0.92388  0.38268 0"/>
        <site name="lidar_ray_08"  pos="0 0 0.03" class="lidar_ray" zaxis="-1.00000  0.00000 0"/>
        <site name="lidar_ray_09"  pos="0 0 0.03" class="lidar_ray" zaxis="-0.92388 -0.38268 0"/>
        <site name="lidar_ray_10"  pos="0 0 0.03" class="lidar_ray" zaxis="-0.70711 -0.70711 0"/>
        <site name="lidar_ray_11"  pos="0 0 0.03" class="lidar_ray" zaxis="-0.38268 -0.92388 0"/>
        <site name="lidar_ray_12"  pos="0 0 0.03" class="lidar_ray" zaxis=" 0.00000 -1.00000 0"/>
        <site name="lidar_ray_13"  pos="0 0 0.03" class="lidar_ray" zaxis=" 0.38268 -0.92388 0"/>
        <site name="lidar_ray_14"  pos="0 0 0.03" class="lidar_ray" zaxis=" 0.70711 -0.70711 0"/>
        <site name="lidar_ray_15"  pos="0 0 0.03" class="lidar_ray" zaxis=" 0.92388 -0.38268 0"/>
      </body>

      <body name="flipper_1_link" pos="-0.24 -0.256 0.06">
        <inertial pos="0 0.00355 0.1515" mass="3.74"
                  quat="0.70709 -0.00453 0.00453 0.70709" diaginertia="0.073 0.066 0.009"/>
        <joint name="flipper_joint_1" axis="0 -1 0" range="-3.14159 3.14159" damping="0.5"/>
        <geom pos="0.24 0.826 -0.06" type="mesh" mesh="flipper_1_1" rgba="0.75 0.75 0.75 1" contype="0" conaffinity="0"/>
        <body name="wheel_flip1_back"  pos="0 0 0">
          <joint name="drive_flip1_back"  type="hinge" axis="0 1 0"/>
          <geom class="wheel" size="0.05 0.04" quat="0.707107 0.707107 0 0"/>
        </body>
        <body name="wheel_flip1_front" pos="0.2 0 0">
          <joint name="drive_flip1_front" type="hinge" axis="0 1 0"/>
          <geom class="wheel" size="0.05 0.04" quat="0.707107 0.707107 0 0"/>
        </body>
      </body>
      <body name="flipper_2_link" pos="0.24 -0.256 0.06">
        <inertial pos="0 -0.00355 0.1515" mass="3.74"
                  quat="0.70709 0.00453 -0.00453 0.70709" diaginertia="0.073 0.066 0.009"/>
        <joint name="flipper_joint_2" axis="0 -1 0" range="-3.14159 3.14159" damping="0.5"/>
        <geom pos="-0.24 0.826 -0.06" type="mesh" mesh="flipper_2_1" rgba="0.75 0.75 0.75 1" contype="0" conaffinity="0"/>
      </body>
      <body name="flipper_3_link" pos="0.24 0.256 0.06">
        <inertial pos="0 -0.00355 0.1515" mass="3.74"
                  quat="0.70709 0.00453 -0.00453 0.70709" diaginertia="0.073 0.066 0.009"/>
        <joint name="flipper_joint_3" axis="0 1 0" range="-3.14159 3.14159" damping="0.5"/>
        <geom pos="0.24 0.276 -0.06" type="mesh" mesh="flipper_3_1" rgba="0.75 0.75 0.75 1" contype="0" conaffinity="0"/>
      </body>
      <body name="flipper_4_link" pos="-0.24 0.256 0.06">
        <inertial pos="0 -0.00355 0.1515" mass="3.74"
                  quat="0.70709 0.00453 -0.00453 0.70709" diaginertia="0.073 0.066 0.009"/>
        <joint name="flipper_joint_4" axis="0 1 0" range="-3.14159 3.14159" damping="0.5"/>
        <geom pos="-0.24 0.276 -0.06" type="mesh" mesh="flipper_4_1" rgba="0.75 0.75 0.75 1" contype="0" conaffinity="0"/>
      </body>

      <body name="link_1" pos="0.12 0 0.2183">
        <inertial pos="0 0 0" mass="1.5" diaginertia="0.01 0.01 0.005"/>
        <joint name="joint_1" axis="0 0 1" range="-3.14 3.14" actuatorfrcrange="-150 150" damping="2.0"/>
        <geom size="0.05 0.05015" pos="0 0.05015 0" quat="0.707107 0.707107 0 0" type="cylinder" rgba="0.7 0.7 0.7 1"/>
        <body name="link_2" pos="0 0.1003 0">
          <inertial pos="0 0 0" mass="1.5" diaginertia="0.01 0.01 0.005"/>
          <joint name="joint_2" axis="0 1 0" range="-3.14 3.14" actuatorfrcrange="-150 150" damping="2.0"/>
          <geom size="0.035 0.17658" pos="0.17658 0 0" quat="0.707107 0 0.707107 0" type="cylinder" rgba="1 0.4 0 1"/>
          <body name="link_3" pos="0.35316 -0.1003 0">
            <inertial pos="0 0 0" mass="1.5" diaginertia="0.01 0.01 0.005"/>
            <joint name="joint_3" axis="0 1 0" range="-3.14 3.14" actuatorfrcrange="-150 150" damping="2.0"/>
            <geom size="0.03 0.233" pos="0.233 0 0" quat="0.707107 0 0.707107 0" type="cylinder" rgba="0.7 0.7 0.7 1"/>
            <body name="link_4" pos="0.466 0.074 0">
              <inertial pos="0 0 0" mass="1.5" diaginertia="0.01 0.01 0.005"/>
              <joint name="joint_4" axis="0 1 0" range="-3.14 3.14" actuatorfrcrange="-50 50" damping="1.0"/>
              <body name="link_5" pos="0.0935 0 0">
                <inertial pos="0 0 0" mass="1.5" diaginertia="0.01 0.01 0.005"/>
                <joint name="joint_5" axis="1 0 0" range="-3.14 3.14" actuatorfrcrange="-50 50" damping="1.0"/>
                <body name="link_6" pos="0 0.0935 0">
                  <inertial pos="0 0 0.00162" mass="1.85" diaginertia="0.0112 0.0112 0.006"/>
                  <joint name="joint_6" axis="0 1 0" range="-3.14 3.14" actuatorfrcrange="-50 50" damping="1.0"/>
                  <geom size="0.04 0.02 0.03" pos="0 0.02 0" type="box" rgba="0.2 0.2 0.2 1"/>
                  <body name="left_finger_link"  pos="-0.035 0.04 0">
                    <inertial pos="0 0 0" mass="0.05" diaginertia="0.0001 0.0001 0.0001"/>
                    <joint name="left_finger_joint"  type="slide" axis="1 0 0" range="0 0.03" actuatorfrcrange="-50 50"/>
                    <geom size="0.005 0.04 0.01" pos="0 0.04 0" type="box" rgba="1 0.4 0 1"/>
                  </body>
                  <body name="right_finger_link" pos="0.035 0.04 0">
                    <inertial pos="0 0 0" mass="0.05" diaginertia="0.0001 0.0001 0.0001"/>
                    <joint name="right_finger_joint" type="slide" axis="-1 0 0" range="0 0.03" actuatorfrcrange="-50 50"/>
                    <geom size="0.005 0.04 0.01" pos="0 0.04 0" type="box" rgba="1 0.4 0 1"/>
                  </body>
                </body>
              </body>
            </body>
          </body>
        </body>
      </body>

      <body name="wheel_l_1" pos="0.24  0.20 -0.10"><joint name="drive_l_1" type="hinge" axis="0 1 0" damping="0.01"/><geom class="track_wheel" size="0.10 0.05" quat="0.707107 0.707107 0 0"/></body>
      <body name="wheel_l_2" pos="0     0.20 -0.10"><joint name="drive_l_2" type="hinge" axis="0 1 0" damping="0.01"/><geom class="track_wheel" size="0.10 0.05" quat="0.707107 0.707107 0 0"/></body>
      <body name="wheel_l_3" pos="-0.24 0.20 -0.10"><joint name="drive_l_3" type="hinge" axis="0 1 0" damping="0.01"/><geom class="track_wheel" size="0.10 0.05" quat="0.707107 0.707107 0 0"/></body>
      <body name="wheel_r_1" pos="0.24 -0.20 -0.10"><joint name="drive_r_1" type="hinge" axis="0 1 0" damping="0.01"/><geom class="track_wheel" size="0.10 0.05" quat="0.707107 0.707107 0 0"/></body>
      <body name="wheel_r_2" pos="0    -0.20 -0.10"><joint name="drive_r_2" type="hinge" axis="0 1 0" damping="0.01"/><geom class="track_wheel" size="0.10 0.05" quat="0.707107 0.707107 0 0"/></body>
      <body name="wheel_r_3" pos="-0.24 -0.20 -0.10"><joint name="drive_r_3" type="hinge" axis="0 1 0" damping="0.01"/><geom class="track_wheel" size="0.10 0.05" quat="0.707107 0.707107 0 0"/></body>
    </body><!-- /footprint_link -->

    <!-- ================== PISTA: PALLETS ================== -->
    <!--
      Mesh visual del conjunto (sólo visual).
      Centroide original URDF: (-0.27, 3.49, 0.08) m.
      body pos=(3,-3.49,0) centra el conjunto a ~x=2.73 sin rotación.
    -->
    <body name="pallets_mesh_body" pos="3 -3.49 0">
      <geom name="pallets_visual" type="mesh" mesh="pallets_mesh"
            contype="0" conaffinity="0" rgba="0.55 0.38 0.18 0.5"/>
    </body>

    <!--
      Colisionadores independientes de la malla:
      Chicana A — bloqueo derecha e izquierda (gap central de 0.8m)
      Chicana B — bloqueo central
      Chicana C — segunda chicana
      Cada "pallet" = box 1.20 × 0.80 × 0.15 m, piso en z=0.075.
    -->

    <!-- === Chicana A (x=2.5m) === -->
    <body name="pallet_A1" pos="2.5  0.80 0.075">
      <geom class="pallet" material="matpallet"/>
    </body>
    <body name="pallet_A2" pos="2.5 -0.80 0.075">
      <geom class="pallet" material="matpallet"/>
    </body>
    <!-- Muros de contención laterales -->
    <body name="wall_A_L" pos="2.5  2.0 0.6">
      <geom type="box" size="0.05 0.60 0.60" material="matwall"/>
    </body>
    <body name="wall_A_R" pos="2.5 -2.0 0.6">
      <geom type="box" size="0.05 0.60 0.60" material="matwall"/>
    </body>

    <!-- === Chicana B (x=3.5m) — bloqueo central, gap a los lados === -->
    <body name="pallet_B1" pos="3.5  0.0 0.075">
      <geom class="pallet" material="matpallet"/>
    </body>
    <!-- pallet apilado (altura +0.15m) simula pila de 2 -->
    <body name="pallet_B2" pos="3.5  0.0 0.225">
      <geom class="pallet" material="matpallet"/>
    </body>

    <!-- === Chicana C (x=4.5m) — espejo de A === -->
    <body name="pallet_C1" pos="4.5  0.80 0.075">
      <geom class="pallet" material="matpallet"/>
    </body>
    <body name="pallet_C2" pos="4.5 -0.80 0.075">
      <geom class="pallet" material="matpallet"/>
    </body>

    <!-- Barrera final (meta) — el robot debe cruzarla -->
    <body name="barrier_goal" pos="5.5 0 0.50">
      <geom type="box" size="0.05 2.50 0.50" rgba="0.2 0.8 0.2 0.4"
            contype="0" conaffinity="0"/>
    </body>

  </worldbody>

  <!-- =================== ACTUADORES =================== -->
  <actuator>
    <velocity name="vel_drive_l_1" joint="drive_l_1" kv="80" ctrlrange="-30 30"/>
    <velocity name="vel_drive_l_2" joint="drive_l_2" kv="80" ctrlrange="-30 30"/>
    <velocity name="vel_drive_l_3" joint="drive_l_3" kv="80" ctrlrange="-30 30"/>
    <velocity name="vel_drive_r_1" joint="drive_r_1" kv="80" ctrlrange="-30 30"/>
    <velocity name="vel_drive_r_2" joint="drive_r_2" kv="80" ctrlrange="-30 30"/>
    <velocity name="vel_drive_r_3" joint="drive_r_3" kv="80" ctrlrange="-30 30"/>
    <velocity name="wheel_left_act"  joint="drive_l_2" kv="80" ctrlrange="-30 30"/>
    <velocity name="wheel_right_act" joint="drive_r_2" kv="80" ctrlrange="-30 30"/>
    <position name="flipper_0_act" joint="flipper_joint_1" kp="250" kv="25" ctrlrange="-3.14159 3.14159"/>
    <position name="flipper_1_act" joint="flipper_joint_2" kp="250" kv="25" ctrlrange="-3.14159 3.14159"/>
    <position name="flipper_2_act" joint="flipper_joint_3" kp="250" kv="25" ctrlrange="-3.14159 3.14159"/>
    <position name="flipper_3_act" joint="flipper_joint_4" kp="250" kv="25" ctrlrange="-3.14159 3.14159"/>
    <position name="joint_1_act" joint="joint_1" kp="400" kv="40" ctrlrange="-3.14159 3.14159"/>
    <position name="joint_2_act" joint="joint_2" kp="400" kv="40" ctrlrange="-3.14159 3.14159"/>
    <position name="joint_3_act" joint="joint_3" kp="400" kv="40" ctrlrange="-3.14159 3.14159"/>
    <position name="joint_4_act" joint="joint_4" kp="200" kv="20" ctrlrange="-3.14159 3.14159"/>
    <position name="joint_5_act" joint="joint_5" kp="200" kv="20" ctrlrange="-3.14159 3.14159"/>
    <position name="joint_6_act" joint="joint_6" kp="200" kv="20" ctrlrange="-3.14159 3.14159"/>
    <position name="pos_left_finger"  joint="left_finger_joint"  kp="50" ctrlrange="0 0.03"/>
    <position name="pos_right_finger" joint="right_finger_joint" kp="50" ctrlrange="0 0.03"/>
    <velocity name="vel_flip1_back"  joint="drive_flip1_back"  kv="5"/>
    <velocity name="vel_flip1_front" joint="drive_flip1_front" kv="5"/>
  </actuator>

  <!-- =================== SENSORES =================== -->
  <sensor>
    <rangefinder name="lidar_distant" site="lidar_origin"/>
    <rangefinder name="rf_00" site="lidar_ray_00"/>
    <rangefinder name="rf_01" site="lidar_ray_01"/>
    <rangefinder name="rf_02" site="lidar_ray_02"/>
    <rangefinder name="rf_03" site="lidar_ray_03"/>
    <rangefinder name="rf_04" site="lidar_ray_04"/>
    <rangefinder name="rf_05" site="lidar_ray_05"/>
    <rangefinder name="rf_06" site="lidar_ray_06"/>
    <rangefinder name="rf_07" site="lidar_ray_07"/>
    <rangefinder name="rf_08" site="lidar_ray_08"/>
    <rangefinder name="rf_09" site="lidar_ray_09"/>
    <rangefinder name="rf_10" site="lidar_ray_10"/>
    <rangefinder name="rf_11" site="lidar_ray_11"/>
    <rangefinder name="rf_12" site="lidar_ray_12"/>
    <rangefinder name="rf_13" site="lidar_ray_13"/>
    <rangefinder name="rf_14" site="lidar_ray_14"/>
    <rangefinder name="rf_15" site="lidar_ray_15"/>
  </sensor>

  <keyframe>
    <!-- nq = 29 (solo robot, sin DOF de pista) -->
    <key name="home"
         qpos="0 0 0.20 1 0 0 0
               0 0 0
               0 0 0
               0 0 0 0 0 0
               0 0
               0 0 0 0 0 0"/>
  </keyframe>

</mujoco>