<?xml version="1.0" ?>
<!-- =================================================================================== -->
<!-- |    This document was autogenerated by xacro from rescue_robot_v2.urdf.xacro     | -->
<!-- |    EDITING THIS FILE BY HAND IS NOT RECOMMENDED                                 | -->
<!-- =================================================================================== -->
<robot name="rescue_robot">
  <!-- ================= MATERIALES ================= -->
  <material name="gray">
    <color rgba="0.7 0.7 0.7 1.0"/>
  </material>
  <material name="orange">
    <color rgba="1.0 0.4 0.0 1.0"/>
  </material>
  <material name="black">
    <color rgba="0.2 0.2 0.2 1.0"/>
  </material>
  <material name="silver">
    <color rgba="0.75 0.75 0.75 1.0"/>
  </material>
  <!-- ================= BASE ROBOT ================= -->
  <link name="base_footprint">
    <visual>
      <geometry>
        <box size="0.001 0.001 0.001"/>
      </geometry>
    </visual>
  </link>
  <joint name="base_to_base_footprint" type="fixed">
    <parent link="base_link"/>
    <child link="base_footprint"/>
    <origin rpy="0 0 0" xyz="0 0 -0.03"/>
  </joint>
  <link name="base_link">
    <inertial>
      <origin rpy="0 0 0" xyz="0 0 0"/>
      <mass value="25"/>
      <inertia ixx="1.238151" ixy="0.0" ixz="0.0" iyy="1.620218" iyz="-0.0" izz="2.702376"/>
    </inertial>
    <visual>
      <origin rpy="0 0 0" xyz="0 0.55 0"/>
      <geometry>
        <mesh filename="package://aesir_robot_description/meshes/base_link.stl" scale="0.001 0.001 0.001"/>
      </geometry>
      <material name="silver"/>
    </visual>
    <collision>
      <origin rpy="0 0 0" xyz="0 0.55 0"/>
      <geometry>
        <mesh filename="package://aesir_robot_description/meshes/base_link.stl" scale="0.001 0.001 0.001"/>
      </geometry>
    </collision>
  </link>
  <link name="tracked_1_link">
    <inertial>
      <origin rpy="0 0 0" xyz="0 0 0"/>
      <mass value="3.5"/>
      <inertia ixx="0.064824" ixy="0.0" ixz="-0.0" iyy="0.377269" iyz="-0.0" izz="0.351452"/>
    </inertial>
    <visual>
      <origin rpy="0 0 0" xyz="0.24 0.806 -0.06"/>
      <geometry>
        <mesh filename="package://aesir_robot_description/meshes/tracked_1.stl" scale="0.001 0.001 0.001"/>
      </geometry>
      <material name="silver"/>
    </visual>
    <collision>
      <origin rpy="0 0 0" xyz="0.24 0.806 -0.06"/>
      <geometry>
        <mesh filename="package://aesir_robot_description/meshes/tracked_1.stl" scale="0.001 0.001 0.001"/>
      </geometry>
    </collision>
  </link>
  <link name="tracked_2_link">
    <inertial>
      <origin rpy="0 0 0" xyz="0 0 0"/>
      <mass value="3.5"/>
      <inertia ixx="0.064824" ixy="0.0" ixz="-0.0" iyy="0.377269" iyz="0.0" izz="0.351452"/>
    </inertial>
    <visual>
      <origin rpy="0 0 0" xyz="0.24 0.306 -0.06"/>
      <geometry>
        <mesh filename="package://aesir_robot_description/meshes/tracked_2.stl" scale="0.001 0.001 0.001"/>
      </geometry>
      <material name="silver"/>
    </visual>
    <collision>
      <origin rpy="0 0 0" xyz="0.24 0.306 -0.06"/>
      <geometry>
        <mesh filename="package://aesir_robot_description/meshes/tracked_2.stl" scale="0.001 0.001 0.001"/>
      </geometry>
    </collision>
  </link>
  <!-- ================= SENSORS ================= -->
  <link name="lidar_link">
    <visual>
      <origin rpy="0 0 0" xyz="0 0 0"/>
      <geometry>
        <mesh filename="package://aesir_robot_description/meshes/lidar.stl" scale="0.001 0.001 0.001"/>
      </geometry>
      <material name="black"/>
    </visual>
    <collision>
      <origin rpy="0 0 0" xyz="0 0 0"/>
      <geometry>
        <mesh filename="package://aesir_robot_description/meshes/lidar.stl" scale="0.001 0.001 0.001"/>
      </geometry>
    </collision>
    <inertial>
      <mass value="0.2"/>
      <inertia ixx="0.001" ixy="0" ixz="0" iyy="0.001" iyz="0" izz="0.001"/>
    </inertial>
  </link>
  <joint name="lidar_joint" type="fixed">
    <parent link="base_link"/>
    <child link="lidar_link"/>
    <origin rpy="0 0.785398 0" xyz="0.320 0 0.105"/>
  </joint>
  <link name="oakd_link">
    <visual>
      <geometry>
        <box size="0.02 0.1 0.03"/>
      </geometry>
      <material name="gray"/>
    </visual>
    <collision>
      <geometry>
        <box size="0.02 0.1 0.03"/>
      </geometry>
    </collision>
    <inertial>
      <mass value="0.1"/>
      <inertia ixx="0.0001" ixy="0" ixz="0" iyy="0.0001" iyz="0" izz="0.0001"/>
    </inertial>
  </link>
  <joint name="oakd_joint" type="fixed">
    <parent link="base_link"/>
    <child link="oakd_link"/>
    <origin rpy="0 0 0" xyz="0.257 0 0.17"/>
  </joint>
  <link name="arm_camera_link">
    <visual>
      <origin rpy="0 0 -1.5708" xyz="0.02 0.04 -0.2"/>
      <geometry>
        <mesh filename="package://aesir_robot_description/meshes/logitech_c920.stl" scale="0.001 0.001 0.001"/>
      </geometry>
      <material name="black"/>
    </visual>
    <collision>
      <origin rpy="0 0 -1.5708" xyz="0.02 0.04 -0.2"/>
      <geometry>
        <mesh filename="package://aesir_robot_description/meshes/logitech_c920.stl" scale="0.001 0.001 0.001"/>
      </geometry>
    </collision>
    <inertial>
      <mass value="0.05"/>
      <inertia ixx="0.00001" ixy="0" ixz="0" iyy="0.00001" iyz="0" izz="0.00001"/>
    </inertial>
  </link>
  <joint name="arm_camera_joint" type="fixed">
    <parent link="link_6"/>
    <child link="arm_camera_link"/>
    <origin rpy="-0.174533 0 0" xyz="0 0 0.06"/>
  </joint>
  <link name="back_camera_link">
    <visual>
      <origin rpy="0 0 3.14159" xyz="0.04 -0.027 -0.19"/>
      <geometry>
        <mesh filename="package://aesir_robot_description/meshes/logitech_c920.stl" scale="0.001 0.001 0.001"/>
      </geometry>
      <material name="black"/>
    </visual>
    <collision>
      <origin rpy="0 0 3.14159" xyz="0.04 -0.027 -0.19"/>
      <geometry>
        <mesh filename="package://aesir_robot_description/meshes/logitech_c920.stl" scale="0.001 0.001 0.001"/>
      </geometry>
    </collision>
    <inertial>
      <mass value="0.05"/>
      <inertia ixx="0.00001" ixy="0" ixz="0" iyy="0.00001" iyz="0" izz="0.00001"/>
    </inertial>
  </link>
  <joint name="back_camera_joint" type="fixed">
    <parent link="base_link"/>
    <child link="back_camera_link"/>
    <origin rpy="0 0 3.14159" xyz="-0.30 0 0.17"/>
  </joint>
  <!-- ================= FLIPPER 1 ================= -->
  <link name="flipper_1_link">
    <inertial>
      <origin rpy="0 0 0" xyz="5.551115123125783e-17 0.003554085914685201 0.15154044804505273"/>
      <mass value="3.742066453745571"/>
      <inertia ixx="0.065573" ixy="0.0" ixz="-0.0" iyy="0.072966" iyz="-0.00082" izz="0.008972"/>
    </inertial>
    <visual>
      <origin rpy="0 0 0" xyz="0.24 0.276 -0.06"/>
      <geometry>
        <mesh filename="package://aesir_robot_description/meshes/flipper_1_1.stl" scale="0.001 0.001 0.001"/>
      </geometry>
      <material name="silver"/>
    </visual>
    <collision>
      <origin rpy="0 0 3.14159" xyz="0.24 0.276 -0.06"/>
      <geometry>
        <mesh filename="package://aesir_robot_description/meshes/flipper_1_1.stl" scale="0.001 0.001 0.001"/>
      </geometry>
    </collision>
  </link>
  <!-- ================= FLIPPER 2 ================= -->
  <link name="flipper_2_link">
    <inertial>
      <origin rpy="0 0 0" xyz="-2.7755575615628914e-17 -0.0035540859146853676 0.15154044804505265"/>
      <mass value="3.7420664537455717"/>
      <inertia ixx="0.065573" ixy="0.0" ixz="0.0" iyy="0.072966" iyz="0.00082" izz="0.008972"/>
    </inertial>
    <visual>
      <origin rpy="0 0 0" xyz="-0.24 0.276 -0.06"/>
      <geometry>
        <mesh filename="package://aesir_robot_description/meshes/flipper_4_1.stl" scale="0.001 0.001 0.001"/>
      </geometry>
      <material name="silver"/>
    </visual>
    <collision>
      <origin rpy="0 0 0" xyz="-0.24 0.276 -0.06"/>
      <geometry>
        <mesh filename="package://aesir_robot_description/meshes/flipper_4_1.stl" scale="0.001 0.001 0.001"/>
      </geometry>
    </collision>
  </link>
  <!-- ================= FLIPPER 3 ================= -->
  <link name="flipper_3_link">
    <inertial>
      <origin rpy="0 0 0" xyz="5.551115123125783e-17 -0.0035540859146853676 0.15154044804505276"/>
      <mass value="3.7420664537455717"/>
      <inertia ixx="0.065573" ixy="-0.0" ixz="0.0" iyy="0.072966" iyz="0.00082" izz="0.008972"/>
    </inertial>
    <visual>
      <origin rpy="0 0 0" xyz="0.24 0.276 -0.06"/>
      <geometry>
        <mesh filename="package://aesir_robot_description/meshes/flipper_3_1.stl" scale="0.001 0.001 0.001"/>
      </geometry>
      <material name="silver"/>
    </visual>
    <collision>
      <origin rpy="0 0 0" xyz="0.24 0.276 -0.06"/>
      <geometry>
        <mesh filename="package://aesir_robot_description/meshes/flipper_3_1.stl" scale="0.001 0.001 0.001"/>
      </geometry>
    </collision>
  </link>
  <!-- ================= FLIPPER 4 ================= -->
  <link name="flipper_4_link">
    <inertial>
      <origin rpy="0 0 0" xyz="-2.7755575615628914e-17 -0.0035540859146853676 0.15154044804505265"/>
      <mass value="3.7420664537455717"/>
      <inertia ixx="0.065573" ixy="0.0" ixz="0.0" iyy="0.072966" iyz="0.00082" izz="0.008972"/>
    </inertial>
    <visual>
      <origin rpy="0 0 0" xyz="-0.24 0.276 -0.06"/>
      <geometry>
        <mesh filename="package://aesir_robot_description/meshes/flipper_4_1.stl" scale="0.001 0.001 0.001"/>
      </geometry>
      <material name="silver"/>
    </visual>
    <collision>
      <origin rpy="0 0 0" xyz="-0.24 0.276 -0.06"/>
      <geometry>
        <mesh filename="package://aesir_robot_description/meshes/flipper_4_1.stl" scale="0.001 0.001 0.001"/>
      </geometry>
    </collision>
  </link>
  <!-- ================= JOINTS BASE AND FLIPPERS ================= -->
  <joint name="Rigid 1" type="fixed">
    <origin rpy="0 0 0" xyz="-0.24 -0.256 0.06"/>
    <parent link="base_link"/>
    <child link="tracked_1_link"/>
  </joint>
  <joint name="Rigid 2" type="fixed">
    <origin rpy="0 0 0" xyz="-0.24 0.256 0.06"/>
    <parent link="base_link"/>
    <child link="tracked_2_link"/>
  </joint>
  <joint name="flipper_joint_1" type="continuous">
    <origin rpy="0 0 0" xyz="-0.24 -0.256 0.06"/>
    <parent link="base_link"/>
    <child link="flipper_1_link"/>
    <axis xyz="0.0 -1.0 0.0"/>
  </joint>
  <joint name="flipper_joint_2" type="continuous">
    <origin rpy="0 0 0" xyz="0.24 -0.256 0.06"/>
    <parent link="base_link"/>
    <child link="flipper_2_link"/>
    <axis xyz="0.0 -1.0 0.0"/>
  </joint>
  <joint name="flipper_joint_3" type="continuous">
    <origin rpy="0 0 0" xyz="0.24 0.256 0.06"/>
    <parent link="base_link"/>
    <child link="flipper_4_link"/>
    <axis xyz="0.0 1.0 0.0"/>
  </joint>
  <joint name="flipper_joint_4" type="continuous">
    <origin rpy="0 0 0" xyz="-0.24 0.256 0.06"/>
    <parent link="base_link"/>
    <child link="flipper_3_link"/>
    <axis xyz="0.0 1.0 0.0"/>
  </joint>
  <!-- ================= BASE ARM ================= -->
  <joint name="arm_mount_joint" type="fixed">
    <parent link="base_link"/>
    <child link="arm_base_link"/>
    <origin rpy="0 0 0" xyz="0.12 0 0.06"/>
  </joint>
  <link name="arm_base_link">
    <visual>
      <origin rpy="0 0 0" xyz="0 0 0.07915"/>
      <geometry>
        <cylinder length="0.1583" radius="0.06"/>
      </geometry>
      <material name="black"/>
    </visual>
    <collision>
      <origin rpy="0 0 0" xyz="0 0 0.07915"/>
      <geometry>
        <cylinder length="0.1583" radius="0.06"/>
      </geometry>
    </collision>
  </link>
  <!-- ================= JOINT 1 ================= -->
  <joint name="joint_1" type="revolute">
    <parent link="arm_base_link"/>
    <child link="link_1"/>
    <origin rpy="0 0 0" xyz="0 0 0.1583"/>
    <axis xyz="0 0 1"/>
    <limit effort="150.0" lower="-3.14" upper="3.14" velocity="3.14"/>
  </joint>
  <link name="link_1">
    <visual>
      <origin rpy="1.5707963267948966 0 0" xyz="0 0.05015 0"/>
      <geometry>
        <cylinder length="0.1003" radius="0.05"/>
      </geometry>
      <material name="gray"/>
    </visual>
    <collision>
      <origin rpy="1.5707963267948966 0 0" xyz="0 0.05015 0"/>
      <geometry>
        <cylinder length="0.1003" radius="0.05"/>
      </geometry>
    </collision>
    <inertial>
      <origin rpy="0 0 0" xyz="0 0 0"/>
      <mass value="1.5"/>
      <inertia ixx="0.01" ixy="0" ixz="0" iyy="0.01" iyz="0" izz="0.005"/>
    </inertial>
  </link>
  <!-- ================= JOINT 2 ================= -->
  <joint name="joint_2" type="revolute">
    <parent link="link_1"/>
    <child link="link_2"/>
    <origin rpy="0 0 0" xyz="0 0.1003 0"/>
    <axis xyz="0 1 0"/>
    <limit effort="150.0" lower="-3.14" upper="3.14" velocity="3.14"/>
  </joint>
  <link name="link_2">
    <visual>
      <origin rpy="0 1.5707963267948966 0" xyz="0.17658 0 0"/>
      <geometry>
        <cylinder length="0.35316" radius="0.035"/>
      </geometry>
      <material name="orange"/>
    </visual>
    <collision>
      <origin rpy="0 1.5707963267948966 0" xyz="0.17658 0 0"/>
      <geometry>
        <cylinder length="0.35316" radius="0.035"/>
      </geometry>
    </collision>
    <visual>
      <origin rpy="1.5707963267948966 0 0" xyz="0.35316 -0.05015 0"/>
      <geometry>
        <cylinder length="0.1003" radius="0.04"/>
      </geometry>
      <material name="black"/>
    </visual>
    <collision>
      <origin rpy="1.5707963267948966 0 0" xyz="0.35316 -0.05015 0"/>
      <geometry>
        <cylinder length="0.1003" radius="0.04"/>
      </geometry>
    </collision>
    <inertial>
      <origin rpy="0 0 0" xyz="0 0 0"/>
      <mass value="1.5"/>
      <inertia ixx="0.01" ixy="0" ixz="0" iyy="0.01" iyz="0" izz="0.005"/>
    </inertial>
  </link>
  <!-- ================= JOINT 3 ================= -->
  <joint name="joint_3" type="revolute">
    <parent link="link_2"/>
    <child link="link_3"/>
    <origin rpy="0 0 0" xyz="0.35316 -0.1003 0"/>
    <axis xyz="0 1 0"/>
    <limit effort="150.0" lower="-3.14" upper="3.14" velocity="3.14"/>
  </joint>
  <link name="link_3">
    <visual>
      <origin rpy="0 1.5707963267948966 0" xyz="0.233 0 0"/>
      <geometry>
        <cylinder length="0.466" radius="0.03"/>
      </geometry>
      <material name="gray"/>
    </visual>
    <collision>
      <origin rpy="0 1.5707963267948966 0" xyz="0.233 0 0"/>
      <geometry>
        <cylinder length="0.466" radius="0.03"/>
      </geometry>
    </collision>
    <visual>
      <origin rpy="1.5707963267948966 0 0" xyz="0.466 0.037 0"/>
      <geometry>
        <cylinder length="0.074" radius="0.03"/>
      </geometry>
      <material name="orange"/>
    </visual>
    <collision>
      <origin rpy="1.5707963267948966 0 0" xyz="0.466 0.037 0"/>
      <geometry>
        <cylinder length="0.074" radius="0.03"/>
      </geometry>
    </collision>
    <inertial>
      <origin rpy="0 0 0" xyz="0 0 0"/>
      <mass value="1.5"/>
      <inertia ixx="0.01" ixy="0" ixz="0" iyy="0.01" iyz="0" izz="0.005"/>
    </inertial>
  </link>
  <!-- ================= JOINT 4 ================= -->
  <joint name="joint_4" type="revolute">
    <parent link="link_3"/>
    <child link="link_4"/>
    <origin rpy="0 0 0" xyz="0.466 0.074 0"/>
    <axis xyz="0 1 0"/>
    <limit effort="50.0" lower="-3.14" upper="3.14" velocity="3.14"/>
  </joint>
  <link name="link_4">
    <visual>
      <origin rpy="0 1.5707963267948966 0" xyz="0.04675 0 0"/>
      <geometry>
        <cylinder length="0.0935" radius="0.025"/>
      </geometry>
      <material name="black"/>
    </visual>
    <collision>
      <origin rpy="0 1.5707963267948966 0" xyz="0.04675 0 0"/>
      <geometry>
        <cylinder length="0.0935" radius="0.025"/>
      </geometry>
    </collision>
    <inertial>
      <origin rpy="0 0 0" xyz="0 0 0"/>
      <mass value="1.5"/>
      <inertia ixx="0.01" ixy="0" ixz="0" iyy="0.01" iyz="0" izz="0.005"/>
    </inertial>
  </link>
  <!-- ================= JOINT 5 ================= -->
  <joint name="joint_5" type="revolute">
    <parent link="link_4"/>
    <child link="link_5"/>
    <origin rpy="0 0 0" xyz="0.0935 0 0"/>
    <axis xyz="1 0 0"/>
    <limit effort="50.0" lower="-3.14" upper="3.14" velocity="3.14"/>
  </joint>
  <link name="link_5">
    <visual>
      <origin rpy="1.5707963267948966 0 0" xyz="0 0.04675 0"/>
      <geometry>
        <cylinder length="0.0935" radius="0.025"/>
      </geometry>
      <material name="gray"/>
    </visual>
    <collision>
      <origin rpy="1.5707963267948966 0 0" xyz="0 0.04675 0"/>
      <geometry>
        <cylinder length="0.0935" radius="0.025"/>
      </geometry>
    </collision>
    <inertial>
      <origin rpy="0 0 0" xyz="0 0 0"/>
      <mass value="1.5"/>
      <inertia ixx="0.01" ixy="0" ixz="0" iyy="0.01" iyz="0" izz="0.005"/>
    </inertial>
  </link>
  <!-- ================= JOINT 6 ================= -->
  <joint name="joint_6" type="revolute">
    <parent link="link_5"/>
    <child link="link_6"/>
    <origin rpy="0 0 0" xyz="0 0.0935 0"/>
    <axis xyz="0 1 0"/>
    <limit effort="50.0" lower="-3.14" upper="3.14" velocity="3.14"/>
  </joint>
  <link name="link_6">
    <visual>
      <origin rpy="-1.5707963267948966 0 0" xyz="0 0 0"/>
      <geometry>
        <cylinder length="0.001" radius="0.01"/>
      </geometry>
      <material name="orange"/>
    </visual>
    <collision>
      <origin rpy="-1.5707963267948966 0 0" xyz="0 0 0"/>
      <geometry>
        <cylinder length="0.001" radius="0.01"/>
      </geometry>
    </collision>
    <inertial>
      <origin rpy="0 0 0" xyz="0 0 0"/>
      <mass value="1.5"/>
      <inertia ixx="0.01" ixy="0" ixz="0" iyy="0.01" iyz="0" izz="0.005"/>
    </inertial>
  </link>
  <!-- ================= GRIPPER ================= -->
  <link name="gripper_base_link">
    <visual>
      <origin rpy="0 0 0" xyz="0 0.02 0"/>
      <geometry>
        <box size="0.08 0.04 0.06"/>
      </geometry>
      <material name="black"/>
    </visual>
    <collision>
      <origin rpy="0 0 0" xyz="0 0.02 0"/>
      <geometry>
        <box size="0.08 0.04 0.06"/>
      </geometry>
    </collision>
    <inertial>
      <mass value="0.3"/>
      <inertia ixx="0.001" ixy="0" ixz="0" iyy="0.001" iyz="0" izz="0.001"/>
    </inertial>
  </link>
  <joint name="gripper_mount_joint" type="fixed">
    <parent link="link_6"/>
    <child link="gripper_base_link"/>
    <origin rpy="0 0 0" xyz="0 0 0"/>
  </joint>
  <link name="left_finger_link">
    <visual>
      <origin rpy="0 0 0" xyz="0 0.04 0"/>
      <geometry>
        <box size="0.01 0.08 0.02"/>
      </geometry>
      <material name="orange"/>
    </visual>
    <collision>
      <origin rpy="0 0 0" xyz="0 0.04 0"/>
      <geometry>
        <box size="0.01 0.08 0.02"/>
      </geometry>
    </collision>
    <inertial>
      <mass value="0.05"/>
      <inertia ixx="0.0001" ixy="0" ixz="0" iyy="0.0001" iyz="0" izz="0.0001"/>
    </inertial>
  </link>
  <joint name="left_finger_joint" type="prismatic">
    <parent link="gripper_base_link"/>
    <child link="left_finger_link"/>
    <origin rpy="0 0 0" xyz="-0.035 0.04 0"/>
    <axis xyz="1 0 0"/>
    <limit effort="50.0" lower="0" upper="0.03" velocity="0.5"/>
  </joint>
  <link name="right_finger_link">
    <visual>
      <origin rpy="0 0 0" xyz="0 0.04 0"/>
      <geometry>
        <box size="0.01 0.08 0.02"/>
      </geometry>
      <material name="orange"/>
    </visual>
    <collision>
      <origin rpy="0 0 0" xyz="0 0.04 0"/>
      <geometry>
        <box size="0.01 0.08 0.02"/>
      </geometry>
    </collision>
    <inertial>
      <mass value="0.05"/>
      <inertia ixx="0.0001" ixy="0" ixz="0" iyy="0.0001" iyz="0" izz="0.0001"/>
    </inertial>
  </link>
  <joint name="right_finger_joint" type="prismatic">
    <parent link="gripper_base_link"/>
    <child link="right_finger_link"/>
    <origin rpy="0 0 0" xyz="0.035 0.04 0"/>
    <axis xyz="-1 0 0"/>
    <limit effort="50.0" lower="0" upper="0.03" velocity="0.5"/>
  </joint>
</robot>
