<!--
============================================================
  AESIR RESCUE ROBOT  -  Escena unificada (robot + pista "Puerta")
  ----------------------------------------------------------
  - Robot:  tracción por orugas (3 ruedas/lado) + 4 flippers
            + brazo 6 DOF + gripper paralelo
  - Pista:  marco + puerta abatible + manija (track "Puerta")
  - Sensors: rangefinder x16 alrededor del LiDAR (360°)
  - Cámaras: 3 estratégicas (cenital, frente-puerta, chase)

  IMPORTANTE
  ----------
  Las mallas originales están referenciadas con ruta relativa
  a   ./meshes/   . Si tus STLs viven en otra carpeta, edita
  el atributo  meshdir  del <compiler> debajo, o copia los
  archivos *.stl en  ./meshes/.
  Si las mallas no están disponibles, los geom de tipo mesh
  son solo visuales (contype=0 conaffinity=0); los colisiona-
  dores son primitivas, por lo que la simulación corre igual.
============================================================
-->
<mujoco model="aesir_rescue_scene">

  <compiler angle="radian" autolimits="true" meshdir="meshes"/>

  <option timestep="0.002" iterations="50" tolerance="1e-10"
          solver="Newton" integrator="implicitfast"
          cone="elliptic" impratio="10"/>

  <size njmax="1000" nconmax="500" nstack="2000000"/>

  <visual>
    <headlight diffuse="0.6 0.6 0.6" ambient="0.3 0.3 0.3" specular="0 0 0"/>
    <rgba haze="0.15 0.25 0.35 1"/>
    <global azimuth="120" elevation="-20"/>
    <map znear="0.01" zfar="50"/>
  </visual>

  <default>
    <default class="wheel">
      <geom type="cylinder" friction="1.5 0.01 0.001"
            condim="6" rgba="0.1 0.1 0.1 1"/>
    </default>
    <default class="track_wheel">
      <geom type="cylinder" friction="2.0 0.02 0.002"
            condim="6" rgba="0.05 0.05 0.05 1"/>
    </default>
    <default class="lidar_ray">
      <site type="sphere" size="0.003" rgba="1 0 0 0.4" group="3"/>
    </default>
  </default>

  <asset>
    <!-- Mallas del robot (visuales) -->
    <mesh name="base_link"   file="base_link.stl"   scale="0.001 0.001 0.001"/>
    <mesh name="tracked_1"   file="tracked_1.stl"   scale="0.001 0.001 0.001"/>
    <mesh name="tracked_2"   file="tracked_2.stl"   scale="0.001 0.001 0.001"/>
    <mesh name="flipper_1_1" file="flipper_1_1.stl" scale="0.001 0.001 0.001"/>
    <mesh name="flipper_4_1" file="flipper_4_1.stl" scale="0.001 0.001 0.001"/>
    <mesh name="flipper_3_1" file="flipper_3_1.stl" scale="0.001 0.001 0.001"/>
    <mesh name="flipper_2_1" file="flipper_2_1.stl" scale="0.001 0.001 0.001"/>
    <mesh name="lidar"       file="lidar.stl"       scale="0.001 0.001 0.001"/>
    <mesh name="logitech_c920" file="logitech_c920.stl" scale="0.001 0.001 0.001"/>

    <!-- Texturas -->
    <texture name="texplane" type="2d" builtin="checker"
             rgb1=".2 .3 .4" rgb2=".1 0.15 0.2"
             width="512" height="512"/>
    <material name="matplane" reflectance="0.3" texture="texplane"
              texrepeat="4 4" texuniform="true"/>

    <texture name="texwall" type="2d" builtin="flat"
             rgb1="0.6 0.55 0.45" width="64" height="64"/>
    <material name="matwall" texture="texwall" specular="0.1"/>

    <material name="matdoor"  rgba="0.55 0.35 0.20 1"/>
    <material name="matframe" rgba="0.35 0.30 0.25 1"/>
    <material name="mathandle" rgba="0.85 0.80 0.10 1"/>
  </asset>

  <!--========================== WORLDBODY ==========================-->
  <worldbody>

    <!-- Iluminación -->
    <light directional="true" diffuse=".8 .8 .8" specular=".2 .2 .2"
           pos="0 0 5" dir="0 0 -1"/>
    <light directional="false" pos="3 0 3" dir="-1 0 -1"
           diffuse="0.4 0.4 0.4"/>

    <!-- Suelo -->
    <geom name="floor" type="plane" size="10 10 0.1" pos="0 0 0"
          material="matplane"/>

    <!--==================  CÁMARAS  ==================-->
    <!-- (1) Cenital - vista de pájaro -->
    <camera name="cam_overview" pos="2 0 6" euler="0 0 -1.5707"
            fovy="60" mode="fixed"/>

    <!-- (2) Frente a la puerta, apuntando al robot (sigue al robot) -->
    <camera name="cam_door" pos="4.5 0 1.2" euler="1.3 1.5707 0"
            fovy="55" mode="targetbody" target="footprint_link"/>

    <!-- (3) Chase cam: se monta en el robot, ver más abajo -->

    <!--==================  ROBOT AESIR  ==================-->
    <body name="footprint_link" pos="0 0 0.20">
      <freejoint name="base_freejoint"/>
      <inertial pos="0 0 0.06" mass="25.0"
                diaginertia="1.2 1.6 2.7"/>

      <!-- Cuerpo principal: caja visual + collider FINO arriba para no
           intersectar las ruedas (la altura del robot está dada por las
           ruedas/orugas que tocan el suelo). -->
      <geom name="chassis_visual" type="box" size="0.30 0.18 0.05"
            pos="0 0 0.10" rgba="0.30 0.32 0.36 1"
            contype="0" conaffinity="0"/>
      <geom name="chassis_col"    type="box" size="0.30 0.18 0.03"
            pos="0 0 0.12" rgba="0.30 0.32 0.36 0.1"
            friction="0.5 0.01 0.001"/>

      <!-- Geometrías visuales por malla (sin colisión) -->
      <geom pos="0 0.55 0" type="mesh" rgba="0.75 0.75 0.75 1"
            mesh="base_link"   contype="0" conaffinity="0"/>
      <geom pos="0 0.55 0" type="mesh" rgba="0.75 0.75 0.75 1"
            mesh="tracked_1"   contype="0" conaffinity="0"/>
      <geom pos="0 0.562 0" type="mesh" rgba="0.75 0.75 0.75 1"
            mesh="tracked_2"   contype="0" conaffinity="0"/>

      <!-- Torreta cilíndrica (base del brazo) -->
      <geom size="0.06 0.07915" pos="0.12 0 0.13915"
            type="cylinder" rgba="0.2 0.2 0.2 1"/>

      <!-- Cámara CHASE montada en el robot -->
      <camera name="cam_chase" pos="-0.9 0 0.7" xyaxes="0 -1 0  0.5 0 1"
              fovy="65" mode="fixed"/>

      <!-- LiDAR -->
      <body name="sensor_lidar" pos="0.32 0 0.105">
        <geom quat="0.92388 0 0.382683 0" type="mesh"
              rgba="0.2 0.2 0.2 1" mesh="lidar"
              contype="0" conaffinity="0"/>

        <!-- Sitio canónico para el rangefinder original -->
        <site name="lidar_origin" pos="0 0 0.03" type="sphere"
              size="0.005" rgba="1 0 0 1"/>

        <!-- ANILLO DE 16 RAYOS A 360° (cada 22.5°)
             zaxis apunta radial hacia afuera en el plano XY -->
        <site name="lidar_ray_00" pos="0 0 0.03" class="lidar_ray"
              zaxis=" 1.00000  0.00000 0"/>
        <site name="lidar_ray_01" pos="0 0 0.03" class="lidar_ray"
              zaxis=" 0.92388  0.38268 0"/>
        <site name="lidar_ray_02" pos="0 0 0.03" class="lidar_ray"
              zaxis=" 0.70711  0.70711 0"/>
        <site name="lidar_ray_03" pos="0 0 0.03" class="lidar_ray"
              zaxis=" 0.38268  0.92388 0"/>
        <site name="lidar_ray_04" pos="0 0 0.03" class="lidar_ray"
              zaxis=" 0.00000  1.00000 0"/>
        <site name="lidar_ray_05" pos="0 0 0.03" class="lidar_ray"
              zaxis="-0.38268  0.92388 0"/>
        <site name="lidar_ray_06" pos="0 0 0.03" class="lidar_ray"
              zaxis="-0.70711  0.70711 0"/>
        <site name="lidar_ray_07" pos="0 0 0.03" class="lidar_ray"
              zaxis="-0.92388  0.38268 0"/>
        <site name="lidar_ray_08" pos="0 0 0.03" class="lidar_ray"
              zaxis="-1.00000  0.00000 0"/>
        <site name="lidar_ray_09" pos="0 0 0.03" class="lidar_ray"
              zaxis="-0.92388 -0.38268 0"/>
        <site name="lidar_ray_10" pos="0 0 0.03" class="lidar_ray"
              zaxis="-0.70711 -0.70711 0"/>
        <site name="lidar_ray_11" pos="0 0 0.03" class="lidar_ray"
              zaxis="-0.38268 -0.92388 0"/>
        <site name="lidar_ray_12" pos="0 0 0.03" class="lidar_ray"
              zaxis=" 0.00000 -1.00000 0"/>
        <site name="lidar_ray_13" pos="0 0 0.03" class="lidar_ray"
              zaxis=" 0.38268 -0.92388 0"/>
        <site name="lidar_ray_14" pos="0 0 0.03" class="lidar_ray"
              zaxis=" 0.70711 -0.70711 0"/>
        <site name="lidar_ray_15" pos="0 0 0.03" class="lidar_ray"
              zaxis=" 0.92388 -0.38268 0"/>
      </body>

      <!-- Cámara delantera (decorativa, ya existía) -->
      <geom size="0.01 0.05 0.015" pos="0.257 0 0.17" type="box"
            rgba="0.7 0.7 0.7 1"/>
      <geom pos="-0.34 0.027 -0.02" quat="-1 0 0 2.65359e-06"
            type="mesh" rgba="0.2 0.2 0.2 1" mesh="logitech_c920"
            contype="0" conaffinity="0"/>

      <!--======== FLIPPER 1 (BL: back-left) ========-->
      <body name="flipper_1_link" pos="-0.24 -0.256 0.06">
        <inertial pos="0 0.00355 0.1515" mass="3.74"
                  quat="0.70709 -0.00453 0.00453 0.70709"
                  diaginertia="0.073 0.066 0.009"/>
        <joint name="flipper_joint_1" pos="0 0 0" axis="0 -1 0"
               range="-3.14159 3.14159" damping="0.5"/>
        <geom pos="0.24 0.826 -0.06" type="mesh"
              rgba="0.75 0.75 0.75 1" mesh="flipper_1_1"
              contype="0" conaffinity="0"/>

        <!-- Mini-ruedas en el flipper 1 (extras) -->
        <body name="wheel_flip1_back" pos="0 0 0">
          <joint name="drive_flip1_back" type="hinge" axis="0 1 0"/>
          <geom class="wheel" size="0.05 0.04"
                quat="0.707107 0.707107 0 0"/>
        </body>
        <body name="wheel_flip1_front" pos="0.2 0 0">
          <joint name="drive_flip1_front" type="hinge" axis="0 1 0"/>
          <geom class="wheel" size="0.05 0.04"
                quat="0.707107 0.707107 0 0"/>
        </body>
      </body>

      <!--======== FLIPPER 2 (BR: back-right) ========-->
      <body name="flipper_2_link" pos="0.24 -0.256 0.06">
        <inertial pos="0 -0.00355 0.1515" mass="3.74"
                  quat="0.70709 0.00453 -0.00453 0.70709"
                  diaginertia="0.073 0.066 0.009"/>
        <joint name="flipper_joint_2" pos="0 0 0" axis="0 -1 0"
               range="-3.14159 3.14159" damping="0.5"/>
        <geom pos="-0.24 0.826 -0.06" type="mesh"
              rgba="0.75 0.75 0.75 1" mesh="flipper_2_1"
              contype="0" conaffinity="0"/>
      </body>

      <!--======== FLIPPER 3 (FR: front-right) ========-->
      <body name="flipper_3_link" pos="0.24 0.256 0.06">
        <inertial pos="0 -0.00355 0.1515" mass="3.74"
                  quat="0.70709 0.00453 -0.00453 0.70709"
                  diaginertia="0.073 0.066 0.009"/>
        <joint name="flipper_joint_3" pos="0 0 0" axis="0 1 0"
               range="-3.14159 3.14159" damping="0.5"/>
        <geom pos="0.24 0.276 -0.06" type="mesh"
              rgba="0.75 0.75 0.75 1" mesh="flipper_3_1"
              contype="0" conaffinity="0"/>
      </body>

      <!--======== FLIPPER 4 (FL: front-left) ========-->
      <body name="flipper_4_link" pos="-0.24 0.256 0.06">
        <inertial pos="0 -0.00355 0.1515" mass="3.74"
                  quat="0.70709 0.00453 -0.00453 0.70709"
                  diaginertia="0.073 0.066 0.009"/>
        <joint name="flipper_joint_4" pos="0 0 0" axis="0 1 0"
               range="-3.14159 3.14159" damping="0.5"/>
        <geom pos="-0.24 0.276 -0.06" type="mesh"
              rgba="0.75 0.75 0.75 1" mesh="flipper_4_1"
              contype="0" conaffinity="0"/>
      </body>

      <!--======== BRAZO 6 DOF ========-->
      <body name="link_1" pos="0.12 0 0.2183">
        <inertial pos="0 0 0" mass="1.5" diaginertia="0.01 0.01 0.005"/>
        <joint name="joint_1" pos="0 0 0" axis="0 0 1"
               range="-3.14 3.14" actuatorfrcrange="-150 150"
               damping="2.0"/>
        <geom size="0.05 0.05015" pos="0 0.05015 0"
              quat="0.707107 0.707107 0 0" type="cylinder"
              rgba="0.7 0.7 0.7 1"/>

        <body name="link_2" pos="0 0.1003 0">
          <inertial pos="0 0 0" mass="1.5" diaginertia="0.01 0.01 0.005"/>
          <joint name="joint_2" pos="0 0 0" axis="0 1 0"
                 range="-3.14 3.14" actuatorfrcrange="-150 150"
                 damping="2.0"/>
          <geom size="0.035 0.17658" pos="0.17658 0 0"
                quat="0.707107 0 0.707107 0" type="cylinder"
                rgba="1 0.4 0 1"/>
          <geom size="0.04 0.05015" pos="0.35316 -0.05015 0"
                quat="0.707107 0.707107 0 0" type="cylinder"
                rgba="0.2 0.2 0.2 1"/>

          <body name="link_3" pos="0.35316 -0.1003 0">
            <inertial pos="0 0 0" mass="1.5"
                      diaginertia="0.01 0.01 0.005"/>
            <joint name="joint_3" pos="0 0 0" axis="0 1 0"
                   range="-3.14 3.14" actuatorfrcrange="-150 150"
                   damping="2.0"/>
            <geom size="0.03 0.233" pos="0.233 0 0"
                  quat="0.707107 0 0.707107 0" type="cylinder"
                  rgba="0.7 0.7 0.7 1"/>
            <geom size="0.03 0.037" pos="0.466 0.037 0"
                  quat="0.707107 0.707107 0 0" type="cylinder"
                  rgba="1 0.4 0 1"/>

            <body name="link_4" pos="0.466 0.074 0">
              <inertial pos="0 0 0" mass="1.5"
                        diaginertia="0.01 0.01 0.005"/>
              <joint name="joint_4" pos="0 0 0" axis="0 1 0"
                     range="-3.14 3.14" actuatorfrcrange="-50 50"
                     damping="1.0"/>
              <geom size="0.025 0.04675" pos="0.04675 0 0"
                    quat="0.707107 0 0.707107 0" type="cylinder"
                    rgba="0.2 0.2 0.2 1"/>

              <body name="link_5" pos="0.0935 0 0">
                <inertial pos="0 0 0" mass="1.5"
                          diaginertia="0.01 0.01 0.005"/>
                <joint name="joint_5" pos="0 0 0" axis="1 0 0"
                       range="-3.14 3.14" actuatorfrcrange="-50 50"
                       damping="1.0"/>
                <geom size="0.025 0.04675" pos="0 0.04675 0"
                      quat="0.707107 0.707107 0 0" type="cylinder"
                      rgba="0.7 0.7 0.7 1"/>

                <body name="link_6" pos="0 0.0935 0">
                  <inertial pos="0 0 0.00162" mass="1.85"
                            diaginertia="0.0112 0.0112 0.006"/>
                  <joint name="joint_6" pos="0 0 0" axis="0 1 0"
                         range="-3.14 3.14"
                         actuatorfrcrange="-50 50" damping="1.0"/>
                  <geom size="0.01 0.0005"
                        quat="0.707107 -0.707107 0 0"
                        type="cylinder" rgba="1 0.4 0 1"/>
                  <geom size="0.04 0.02 0.03" pos="0 0.02 0"
                        type="box" rgba="0.2 0.2 0.2 1"/>
                  <geom pos="0.02 0.00466 -0.144"
                        quat="0.704415 -0.0616 -0.0616 -0.704417"
                        type="mesh" rgba="0.2 0.2 0.2 1"
                        mesh="logitech_c920"
                        contype="0" conaffinity="0"/>

                  <!-- GRIPPER -->
                  <body name="left_finger_link" pos="-0.035 0.04 0">
                    <inertial pos="0 0 0" mass="0.05"
                              diaginertia="0.0001 0.0001 0.0001"/>
                    <joint name="left_finger_joint" type="slide"
                           pos="0 0 0" axis="1 0 0"
                           range="0 0.03"
                           actuatorfrcrange="-50 50"/>
                    <geom size="0.005 0.04 0.01" pos="0 0.04 0"
                          type="box" rgba="1 0.4 0 1"/>
                  </body>
                  <body name="right_finger_link" pos="0.035 0.04 0">
                    <inertial pos="0 0 0" mass="0.05"
                              diaginertia="0.0001 0.0001 0.0001"/>
                    <joint name="right_finger_joint" type="slide"
                           pos="0 0 0" axis="-1 0 0"
                           range="0 0.03"
                           actuatorfrcrange="-50 50"/>
                    <geom size="0.005 0.04 0.01" pos="0 0.04 0"
                          type="box" rgba="1 0.4 0 1"/>
                  </body>
                </body>
              </body>
            </body>
          </body>
        </body>
      </body>

      <!--======== RUEDAS DE TRACCIÓN ========-->
      <!-- Cada rueda: cilindro radio 0.10, eje Y (gira sobre Y).
           Posición local Z = -0.10  =>  centro mundial Z = 0.10 (radio),
           el borde inferior toca exactamente el suelo. -->
      <!-- Lado izquierdo (y > 0) -->
      <body name="wheel_l_1" pos="0.24 0.20 -0.10">
        <joint name="drive_l_1" type="hinge" axis="0 1 0"
               damping="0.01"/>
        <geom class="track_wheel" size="0.10 0.05"
              quat="0.707107 0.707107 0 0"/>
      </body>
      <body name="wheel_l_2" pos="0 0.20 -0.10">
        <joint name="drive_l_2" type="hinge" axis="0 1 0"
               damping="0.01"/>
        <geom class="track_wheel" size="0.10 0.05"
              quat="0.707107 0.707107 0 0"/>
      </body>
      <body name="wheel_l_3" pos="-0.24 0.20 -0.10">
        <joint name="drive_l_3" type="hinge" axis="0 1 0"
               damping="0.01"/>
        <geom class="track_wheel" size="0.10 0.05"
              quat="0.707107 0.707107 0 0"/>
      </body>

      <!-- Lado derecho (y < 0) -->
      <body name="wheel_r_1" pos="0.24 -0.20 -0.10">
        <joint name="drive_r_1" type="hinge" axis="0 1 0"
               damping="0.01"/>
        <geom class="track_wheel" size="0.10 0.05"
              quat="0.707107 0.707107 0 0"/>
      </body>
      <body name="wheel_r_2" pos="0 -0.20 -0.10">
        <joint name="drive_r_2" type="hinge" axis="0 1 0"
               damping="0.01"/>
        <geom class="track_wheel" size="0.10 0.05"
              quat="0.707107 0.707107 0 0"/>
      </body>
      <body name="wheel_r_3" pos="-0.24 -0.20 -0.10">
        <joint name="drive_r_3" type="hinge" axis="0 1 0"
               damping="0.01"/>
        <geom class="track_wheel" size="0.10 0.05"
              quat="0.707107 0.707107 0 0"/>
      </body>

    </body><!-- /footprint_link -->

    <!--==================  PISTA "PUERTA"  ==================-->
    <!--
        Marco de la puerta: 2 postes verticales + viga superior.
        Puerta abatible con bisagra vertical (Z) en el poste izq.
        Manija con bisagra horizontal.
        El robot arranca en el origen mirando +X; la puerta está
        a ~3 m enfrente.
    -->
    <body name="door_frame" pos="3.0 0 0">
      <!-- Poste izquierdo (lado de la bisagra) -->
      <geom name="post_left"  type="box" size="0.05 0.05 1.05"
            pos="0  0.55 1.05" material="matframe"/>
      <!-- Poste derecho (lado libre) -->
      <geom name="post_right" type="box" size="0.05 0.05 1.05"
            pos="0 -0.55 1.05" material="matframe"/>
      <!-- Viga superior -->
      <geom name="lintel" type="box" size="0.05 0.6 0.05"
            pos="0 0 2.15" material="matframe"/>
      <!-- Muros laterales (opacos) -->
      <geom name="wall_l" type="box" size="0.05 1.5 1.05"
            pos="0 2.1 1.05" material="matwall"/>
      <geom name="wall_r" type="box" size="0.05 1.5 1.05"
            pos="0 -2.1 1.05" material="matwall"/>

      <!-- HOJA DE LA PUERTA (cuerpo articulado) -->
      <body name="door_leaf" pos="0 0.50 1.05">
        <inertial pos="0 -0.5 0" mass="15.0"
                  diaginertia="3.5 0.05 3.5"/>
        <joint name="door_hinge" type="hinge" axis="0 0 1"
               pos="0 0 0" range="-2.0 2.0"
               damping="3.0" frictionloss="0.5"/>
        <geom name="door_panel" type="box" size="0.02 0.50 1.0"
              pos="0 -0.50 0" material="matdoor"/>

        <!-- Manija (sólo visual + sólido pasivo) -->
        <body name="door_handle" pos="0.03 -0.85 0">
          <inertial pos="0 0 0" mass="0.1"
                    diaginertia="0.0005 0.0005 0.0005"/>
          <joint name="handle_hinge" type="hinge" axis="1 0 0"
                 range="-1.0 0.0" damping="0.3"/>
          <geom name="handle_grip" type="cylinder"
                size="0.012 0.07" euler="0 1.5707 0"
                pos="0.05 0 0" material="mathandle"/>
          <geom name="handle_base" type="box"
                size="0.005 0.02 0.02"
                material="mathandle"/>
        </body>
      </body>
    </body>
  </worldbody>

  <!--==========================  ACTUATORS  ==========================
       Nombres alineados con el ActionAdapter:
       - wheel_left_act / wheel_right_act ........ (genéricos, usan el primer wheel)
       - vel_drive_l_1..3 / vel_drive_r_1..3 .....  (manejados por AesirMujocoAdapter)
       - joint_1_act .. joint_6_act ..............  posición
       - flipper_0_act .. flipper_3_act ..........  posición
       Mapeo flipper_0..3 -> flipper_joint_1..4 (orden BL,BR,FR,FL)
  ====================================================================-->
  <actuator>
    <!-- TRACCIÓN: 3 ruedas/lado con actuador propio
         (la AesirMujocoAdapter replica el mismo target en las 3) -->
    <velocity name="vel_drive_l_1" joint="drive_l_1" kv="80"
              ctrlrange="-30 30"/>
    <velocity name="vel_drive_l_2" joint="drive_l_2" kv="80"
              ctrlrange="-30 30"/>
    <velocity name="vel_drive_l_3" joint="drive_l_3" kv="80"
              ctrlrange="-30 30"/>
    <velocity name="vel_drive_r_1" joint="drive_r_1" kv="80"
              ctrlrange="-30 30"/>
    <velocity name="vel_drive_r_2" joint="drive_r_2" kv="80"
              ctrlrange="-30 30"/>
    <velocity name="vel_drive_r_3" joint="drive_r_3" kv="80"
              ctrlrange="-30 30"/>

    <!-- Alias 1-a-1 con nombre canónico del MujocoAdapter
         (apuntan a la rueda central de cada lado; AesirMujocoAdapter
          NO los usa directamente, pero permiten el lookup base sin
          fallar si alguien instancia el MujocoAdapter sin override) -->
    <velocity name="wheel_left_act"  joint="drive_l_2" kv="80"
              ctrlrange="-30 30"/>
    <velocity name="wheel_right_act" joint="drive_r_2" kv="80"
              ctrlrange="-30 30"/>

    <!-- FLIPPERS: posición (kp + kv para amortiguar)
         Orden: flipper_0=BL, flipper_1=BR, flipper_2=FR, flipper_3=FL -->
    <position name="flipper_0_act" joint="flipper_joint_1"
              kp="250" kv="25" ctrlrange="-3.14159 3.14159"/>
    <position name="flipper_1_act" joint="flipper_joint_2"
              kp="250" kv="25" ctrlrange="-3.14159 3.14159"/>
    <position name="flipper_2_act" joint="flipper_joint_3"
              kp="250" kv="25" ctrlrange="-3.14159 3.14159"/>
    <position name="flipper_3_act" joint="flipper_joint_4"
              kp="250" kv="25" ctrlrange="-3.14159 3.14159"/>

    <!-- BRAZO 6 DOF: posición -->
    <position name="joint_1_act" joint="joint_1" kp="400" kv="40"
              ctrlrange="-3.14159 3.14159"/>
    <position name="joint_2_act" joint="joint_2" kp="400" kv="40"
              ctrlrange="-3.14159 3.14159"/>
    <position name="joint_3_act" joint="joint_3" kp="400" kv="40"
              ctrlrange="-3.14159 3.14159"/>
    <position name="joint_4_act" joint="joint_4" kp="200" kv="20"
              ctrlrange="-3.14159 3.14159"/>
    <position name="joint_5_act" joint="joint_5" kp="200" kv="20"
              ctrlrange="-3.14159 3.14159"/>
    <position name="joint_6_act" joint="joint_6" kp="200" kv="20"
              ctrlrange="-3.14159 3.14159"/>

    <!-- GRIPPER (no expuesto a la política; lo dejamos cerrado) -->
    <position name="pos_left_finger"  joint="left_finger_joint"
              kp="50" ctrlrange="0 0.03"/>
    <position name="pos_right_finger" joint="right_finger_joint"
              kp="50" ctrlrange="0 0.03"/>

    <!-- Mini-wheels del flipper 1 (pasivos para tope/giro libre) -->
    <velocity name="vel_flip1_back"  joint="drive_flip1_back"  kv="5"/>
    <velocity name="vel_flip1_front" joint="drive_flip1_front" kv="5"/>
  </actuator>

  <!--==========================  SENSORS  ==========================-->
  <sensor>
    <!-- Rangefinder canónico solicitado en robot.xacro -->
    <rangefinder name="lidar_distant" site="lidar_origin"/>

    <!-- Anillo LiDAR de 16 rayos a 360° -->
    <rangefinder name="rf_00" site="lidar_ray_00"/>
    <rangefinder name="rf_01" site="lidar_ray_01"/>
    <rangefinder name="rf_02" site="lidar_ray_02"/>
    <rangefinder name="rf_03" site="lidar_ray_03"/>
    <rangefinder name="rf_04" site="lidar_ray_04"/>
    <rangefinder name="rf_05" site="lidar_ray_05"/>
    <rangefinder name="rf_06" site="lidar_ray_06"/>
    <rangefinder name="rf_07" site="lidar_ray_07"/>
    <rangefinder name="rf_08" site="lidar_ray_08"/>
    <rangefinder name="rf_09" site="lidar_ray_09"/>
    <rangefinder name="rf_10" site="lidar_ray_10"/>
    <rangefinder name="rf_11" site="lidar_ray_11"/>
    <rangefinder name="rf_12" site="lidar_ray_12"/>
    <rangefinder name="rf_13" site="lidar_ray_13"/>
    <rangefinder name="rf_14" site="lidar_ray_14"/>
    <rangefinder name="rf_15" site="lidar_ray_15"/>
  </sensor>

  <!--==========================  KEYFRAME ==========================-->
  <keyframe>
    <!-- Pose inicial. Ordenamiento real de qpos:
            [0:7]   base_freejoint    (x,y,z, qw,qx,qy,qz)
            [7]     flipper_joint_1   (BL)
            [8]     drive_flip1_back  (rueda mini)
            [9]     drive_flip1_front (rueda mini)
            [10]    flipper_joint_2   (BR)
            [11]    flipper_joint_3   (FR)
            [12]    flipper_joint_4   (FL)
            [13:19] joint_1..joint_6  (brazo)
            [19:21] left_finger, right_finger (gripper)
            [21:24] drive_l_1..3
            [24:27] drive_r_1..3
            [27]    door_hinge
            [28]    handle_hinge
    -->
    <key name="home"
         qpos="0 0 0.20  1 0 0 0
               0 0 0
               0 0 0
               0 0 0 0 0 0
               0 0
               0 0 0 0 0 0
               0 0"/>
  </keyframe>

</mujoco>
