<?xml version="1.0" ?>
<robot name="(Unsaved)" xmlns:xacro="http://www.ros.org/wiki/xacro">

<xacro:include filename="$(find (Unsaved)_description)/urdf/materials.xacro" />
<xacro:include filename="$(find (Unsaved)_description)/urdf/(Unsaved).trans" />
<xacro:include filename="$(find (Unsaved)_description)/urdf/(Unsaved).gazebo" />
<link name="base_link">
  <inertial>
    <origin xyz="-3.4588481412471766e-15 0.4539467407358336 1.0091284123119322" rpy="0 0 0"/>
    <mass value="227.13701192554538"/>
    <inertia ixx="274.227869" iyy="222.05999" izz="119.714799" ixy="-0.0" iyz="-39.08765" ixz="-0.0"/>
  </inertial>
  <visual>
    <origin xyz="0 0 0" rpy="0 0 0"/>
    <geometry>
      <mesh filename="package://(Unsaved)_description/meshes/base_link.stl" scale="0.001 0.001 0.001"/>
    </geometry>
    <material name="silver"/>
  </visual>
  <collision>
    <origin xyz="0 0 0" rpy="0 0 0"/>
    <geometry>
      <mesh filename="package://(Unsaved)_description/meshes/base_link.stl" scale="0.001 0.001 0.001"/>
    </geometry>
  </collision>
</link>

<link name="puerta_1">
  <inertial>
    <origin xyz="-0.005006862701292476 -0.39841277353803095 1.1251950513879994" rpy="0 0 0"/>
    <mass value="158.51373173715245"/>
    <inertia ixx="72.09553" iyy="61.473256" izz="10.754967" ixy="-0.133511" iyz="0.011642" ixz="0.000146"/>
  </inertial>
  <visual>
    <origin xyz="-0.0 -1.05 -0.009" rpy="0 0 0"/>
    <geometry>
      <mesh filename="package://(Unsaved)_description/meshes/puerta_1.stl" scale="0.001 0.001 0.001"/>
    </geometry>
    <material name="silver"/>
  </visual>
  <collision>
    <origin xyz="-0.0 -1.05 -0.009" rpy="0 0 0"/>
    <geometry>
      <mesh filename="package://(Unsaved)_description/meshes/puerta_1.stl" scale="0.001 0.001 0.001"/>
    </geometry>
  </collision>
</link>

<link name="manija_1">
  <inertial>
    <origin xyz="-0.015062256080142113 0.015705994253239486 -9.778175683572421e-05" rpy="0 0 0"/>
    <mass value="0.8624334414140397"/>
    <inertia ixx="0.001536" iyy="0.003053" izz="0.004046" ixy="1.9e-05" iyz="-1e-06" ixz="-0.0"/>
  </inertial>
  <visual>
    <origin xyz="-0.015513 -0.274365 -1.059" rpy="0 0 0"/>
    <geometry>
      <mesh filename="package://(Unsaved)_description/meshes/manija_1.stl" scale="0.001 0.001 0.001"/>
    </geometry>
    <material name="silver"/>
  </visual>
  <collision>
    <origin xyz="-0.015513 -0.274365 -1.059" rpy="0 0 0"/>
    <geometry>
      <mesh filename="package://(Unsaved)_description/meshes/manija_1.stl" scale="0.001 0.001 0.001"/>
    </geometry>
  </collision>
</link>

<joint name="Revolute 7" type="continuous">
  <origin xyz="0.0 1.05 0.009" rpy="0 0 0"/>
  <parent link="base_link"/>
  <child link="puerta_1"/>
  <axis xyz="0.0 0.0 -1.0"/>
</joint>

<joint name="Revolute 8" type="continuous">
  <origin xyz="0.015513 -0.775635 1.05" rpy="0 0 0"/>
  <parent link="puerta_1"/>
  <child link="manija_1"/>
  <axis xyz="-0.999921 0.012566 0.0"/>
</joint>

</robot>
