<mujoco model="aesir_mapa_completo">

  <compiler angle="radian" autolimits="true" meshdir=""/>

  <asset>
    <texture name="texplane" type="2d" builtin="checker" rgb1=".2 .3 .4" rgb2=".1 0.15 0.2" width="512" height="512"/>
    <material name="matplane" reflectance="0.3" texture="texplane" texrepeat="4 4" texuniform="true"/>
    
    <material name="matdoor" rgba="0.6 0.5 0.4 1"/>
    <material name="mathandle" rgba="1 0.8 0 1"/>

    <mesh name="pallets_mesh" file="meshes/pallets/base_link.stl" scale="0.001 0.001 0.001"/>
    <mesh name="puerta_marco" file="meshes/door/base_link.stl" scale="0.001 0.001 0.001"/>
    <mesh name="puerta_hoja"  file="meshes/door/puerta_1.stl"  scale="0.001 0.001 0.001"/>
    <mesh name="puerta_manija" file="meshes/door/manija_1.stl" scale="0.001 0.001 0.001"/>
  </asset>

  <worldbody>
    <light directional="true" pos="0 0 5" dir="0 0 -1"/>
    
    <geom name="muerte_suelo_penalizacion" type="plane" size="50 50 0.1" pos="0 0 0" material="matplane"/>
        
    <body name="pallets_mesh_body" pos="3 -3.49 0">
      <geom name="pallets_visual" type="mesh" mesh="pallets_mesh" contype="0" conaffinity="0" rgba="0.55 0.38 0.18 1"/>
      <geom name= "fatal_pallet 1" type="box" size=".55 0.6 .12" pos="0 .9 0" rgba="1 0 0 0.5"/>
      <geom name= "fatal_pallet 2" type="box" size=".55 0.6 .12" pos="-.3 2.1 0" rgba="1 0 0 0.5"/>
      <geom name= "fatal_pallet 3" type="box" size=".5 0.6 .12" pos="-.6 3.28 0" rgba="1 0 0 0.5"/>
      <geom name= "fatal_pallet 4" type="box" size=".55 0.6 .12" pos="-1.65 3.28 0" rgba="1 0 0 0.5"/>
      <geom name= "fatal_pallet 5" type="box" size=".55 0.6 .12" pos="-2 4.48 0" rgba="1 0 0 0.5"/>
      <geom name= "fatal_pallet 6" type="box" size=".55 0.6 .12" pos="-3.1 4.8 0" rgba="1 0 0 0.5"/>
      <geom name= "fatal_pallet 7" type="box" size=".55 0.6 .12" pos="-3.4 5.97 0" rgba="1 0 0 0.5"/>
      <geom name= "fatal_pallet 8" type="box" size=".55 0.6 .12" pos="-4.5 5.97 0" rgba="1 0 0 0.5"/>
      <geom name= "fatal_pallet 9" type="box" size=".55 0.6 .12" pos="-4.78 7.2 0" rgba="1 0 0 0.5"/>
      <geom name= "fatal_pallet 10" type="box" size=".55 0.6 .12" pos="-3.7 7.2 0" rgba="1 0 0 0.5"/>
      <geom name= "fatal_pallet 11" type="box" size=".55 0.6 .12" pos="4.8 4.5 0" rgba="1 0 0 0.5"/>
      <geom name= "fatal_pallet 12" type="box" size=".55 0.6 .12" pos="3.7 4.5 0" rgba="1 0 0 0.5"/>
      <geom name= "fatal_pallet 13" type="box" size=".55 0.6 .12" pos="3.4 3.3 0" rgba="1 0 0 0.5"/>
      <geom name= "fatal_pallet 14" type="box" size=".55 0.6 .12" pos="2.3 3.3 0" rgba="1 0 0 0.5"/>
      <geom name= "fatal_pallet 15" type="box" size=".55 0.6 .12" pos="2.0 2.1 0" rgba="1 0 0 0.5"/>
      <geom name= "fatal_pallet 16" type="box" size=".55 0.6 .12" pos="1.7 .9 0" rgba="1 0 0 0.5"/>
      <geom name= "fatal_pallet 17" type="box" size=".55 0.6 .12" pos="1.4 -.3 0" rgba="1 0 0 0.5"/>
      <geom name= "fatal_pallet 18" type="box" size=".55 0.6 .12" pos=".3 -.3 0" rgba="1 0 0 0.5"/>


      <geom name= "fatal_stick 1" type="box" size=".024 0.05 .45" pos=".572 .33 0" rgba="1 0 0 0.5"/>
      <geom name= "fatal_stick 2" type="box" size=".024 0.05 .45" pos="1.127 .33 0" rgba="1 0 0 0.5"/>
      <geom name= "fatal_stick 3" type="box" size=".024 0.05 .45" pos="-.276 .228 0" rgba="1 0 0 0.5"/>
      <geom name= "fatal_stick 4" type="box" size=".024 0.05 .45" pos="-.024 2.724 0" rgba="1 0 0 0.5"/>
      <geom name= "fatal_stick 5" type="box" size=".024 0.05 .45" pos="-.9 2.8 0" rgba="1 0 0 0.5"/>
    

    </body>

    <body name="door_frame" pos="3.7 -2 0.08">
      <geom type="mesh" mesh="puerta_marco" contype="0" conaffinity="0"/>
      <geom name= "door_frame1" type="box" size=".6 0.02 2.35" pos="-0.0009 1.19 0" rgba="1 0 0 0.5"/>
      <geom name= "door_floor" type="box" size=".8 1.2 .03" pos="0 0 0" rgba="1 0 0 0.5"/>


      <body name="door_leaf" pos="0 1.05 0.01">
        <joint name="door_hinge" type="hinge" axis="0 0 1" pos="0 0 0" range="-1.5 1.5" damping="3.0"/>
        <geom name="dl_mesh" type="mesh" mesh="puerta_hoja" pos="0 -1.05 -0.009" material="matdoor" contype="0" conaffinity="0"/>
        <geom name= "door_leaf" type="box" size=".05 0.5 2.25" pos="-0.0009 -0.36 0" rgba="1 0 0 0.5"/>


        <body name="door_handle" pos="0.0 -1.32 -1.06">
          <joint name="handle_hinge" type="hinge" axis="1 0 0" pos="0 0.554 2.103" range="-1.0 0.0" damping="0.3" stiffness="2.0"/>
          <geom name="dh_mesh" type="mesh" mesh="puerta_manija" pos="-0.005 0.27 1.05" material="mathandle" contype="0" conaffinity="0"/>
          <geom name="col_manija" type="cylinder" size="0.12 0.11" pos="0 .56 2.113" euler="0 1.5707 0" rgba="1 0 0 0.5"/>
        </body>
      </body>
    </body>

  </worldbody>
</mujoco>